Workbook

Sheet Venues
A1: NYC Off Tech — Event Venues & Places
A2: All 27 issues, Oct 2, 2025 – Oct 16, 2026 · 796 venue references · 168 distinct venues/places. Counts and dates are live formulas on the Reference Log tab.
A4: Rank | B4: Venue / place | C4: Type | D4: Area / address | E4: Times referenced (event listings) | F4: Issues referencing | G4: First referenced (issue) | H4: Most recent reference (issue) | I4: Latest event date listed | J4: Most recent event listed | K4: Most common host | L4: Host listings (top / with host named)
A5: 1 | B5: Tompkins Square Park | C5: Park / public space | D5: East Village, Manhattan | E5: =COUNTIF('Reference Log'!$E$2:$E$797,B5) -> 106 | F5: =SUMIFS('Reference Log'!$J$2:$J$797,'Reference Log'!$E$2:$E$797,B5) -> 18 | G5: =_xlfn.MINIFS('Reference Log'!$A$2:$A$797,'Reference Log'!$E$2:$E$797,B5) -> 45932 | H5: =_xlfn.MAXIFS('Reference Log'!$A$2:$A$797,'Reference Log'!$E$2:$E$797,B5) -> 46311 | I5: =_xlfn.MAXIFS('Reference Log'!$D$2:$D$797,'Reference Log'!$E$2:$E$797,B5) -> 46326 | J5: Tompkins Distro (weekly) | K5: Summer of Ludd | L5: 57 of 88
A6: 2 | B6: Strother School of Radical Attention (SoRA) | C6: Arts / community space | D6: DUMBO, Brooklyn (listed as 'DUMBO') | E6: =COUNTIF('Reference Log'!$E$2:$E$797,B6) -> 67 | F6: =SUMIFS('Reference Log'!$J$2:$J$797,'Reference Log'!$E$2:$E$797,B6) -> 24 | G6: =_xlfn.MINIFS('Reference Log'!$A$2:$A$797,'Reference Log'!$E$2:$E$797,B6) -> 45932 | H6: =_xlfn.MAXIFS('Reference Log'!$A$2:$A$797,'Reference Log'!$E$2:$E$797,B6) -> 46311 | I6: =_xlfn.MAXIFS('Reference Log'!$D$2:$D$797,'Reference Log'!$E$2:$E$797,B6) -> 46325 | J6: The Dance of an Open Mind: Toni Morrison's Radical Attentions | K6: School of Radical Attention (SoRA) | L6: 57 of 65
A7: 3 | B7: Stavros Niarchos Foundation Library (NYPL) | C7: Library | D7: Midtown, Manhattan | E7: =COUNTIF('Reference Log'!$E$2:$E$797,B7) -> 44 | F7: =SUMIFS('Reference Log'!$J$2:$J$797,'Reference Log'!$E$2:$E$797,B7) -> 24 | G7: =_xlfn.MINIFS('Reference Log'!$A$2:$A$797,'Reference Log'!$E$2:$E$797,B7) -> 45932 | H7: =_xlfn.MAXIFS('Reference Log'!$A$2:$A$797,'Reference Log'!$E$2:$E$797,B7) -> 46311 | I7: =_xlfn.MAXIFS('Reference Log'!$D$2:$D$797,'Reference Log'!$E$2:$E$797,B7) -> 46325 | J7: Crafternoon (weekly) | K7: NYPL Offline Book Club | L7: 21 of 43
A8: 4 | B8: Undisclosed address — Crown Heights | C8: Undisclosed (neighborhood only) | D8: Crown Heights | E8: =COUNTIF('Reference Log'!$E$2:$E$797,B8) -> 31 | F8: =SUMIFS('Reference Log'!$J$2:$J$797,'Reference Log'!$E$2:$E$797,B8) -> 16 | G8: =_xlfn.MINIFS('Reference Log'!$A$2:$A$797,'Reference Log'!$E$2:$E$797,B8) -> 45932 | H8: =_xlfn.MAXIFS('Reference Log'!$A$2:$A$797,'Reference Log'!$E$2:$E$797,B8) -> 46311 | I8: =_xlfn.MAXIFS('Reference Log'!$D$2:$D$797,'Reference Log'!$E$2:$E$797,B8) -> 46324 | J8: Crown Heights Silent Reading (weekly) | K8: Connor Griffin | L8: 20 of 26
A9: 5 | B9: Prospect Park (incl. Boathouse, Fallkill Falls, Rose Garden) | C9: Park / public space | D9: Brooklyn | E9: =COUNTIF('Reference Log'!$E$2:$E$797,B9) -> 31 | F9: =SUMIFS('Reference Log'!$J$2:$J$797,'Reference Log'!$E$2:$E$797,B9) -> 14 | G9: =_xlfn.MINIFS('Reference Log'!$A$2:$A$797,'Reference Log'!$E$2:$E$797,B9) -> 45932 | H9: =_xlfn.MAXIFS('Reference Log'!$A$2:$A$797,'Reference Log'!$E$2:$E$797,B9) -> 46311 | I9: =_xlfn.MAXIFS('Reference Log'!$D$2:$D$797,'Reference Log'!$E$2:$E$797,B9) -> 46333 | J9: Pirates of Prospect Park Annual Treasure Hunt | K9: Kyle Barnes / Chimeras Collective | L9: 6 of 15
A10: 6 | B10: 15th Street Quaker Meeting House (15 Rutherford Pl.) | C10: Church / meeting house | D10: Stuyvesant Square, Manhattan | E10: =COUNTIF('Reference Log'!$E$2:$E$797,B10) -> 24 | F10: =SUMIFS('Reference Log'!$J$2:$J$797,'Reference Log'!$E$2:$E$797,B10) -> 12 | G10: =_xlfn.MINIFS('Reference Log'!$A$2:$A$797,'Reference Log'!$E$2:$E$797,B10) -> 46083 | H10: =_xlfn.MAXIFS('Reference Log'!$A$2:$A$797,'Reference Log'!$E$2:$E$797,B10) -> 46296 | I10: =_xlfn.MAXIFS('Reference Log'!$D$2:$D$797,'Reference Log'!$E$2:$E$797,B10) -> 46299 | J10: The Art of Leonard Peltier Comes to NYC | K10: Summer of Ludd | L10: 9 of 21
A11: 7 | B11: Undisclosed address — Bushwick | C11: Undisclosed (neighborhood only) | D11: Bushwick | E11: =COUNTIF('Reference Log'!$E$2:$E$797,B11) -> 23 | F11: =SUMIFS('Reference Log'!$J$2:$J$797,'Reference Log'!$E$2:$E$797,B11) -> 17 | G11: =_xlfn.MINIFS('Reference Log'!$A$2:$A$797,'Reference Log'!$E$2:$E$797,B11) -> 45962 | H11: =_xlfn.MAXIFS('Reference Log'!$A$2:$A$797,'Reference Log'!$E$2:$E$797,B11) -> 46311 | I11: =_xlfn.MAXIFS('Reference Log'!$D$2:$D$797,'Reference Log'!$E$2:$E$797,B11) -> 46327 | J11: Songwriting Circle | K11: Rebecca Lipsitch (How Do We Play) | L11: 14 of 21
A12: 8 | B12: Washington Square Park | C12: Park / public space | D12: Greenwich Village, Manhattan | E12: =COUNTIF('Reference Log'!$E$2:$E$797,B12) -> 22 | F12: =SUMIFS('Reference Log'!$J$2:$J$797,'Reference Log'!$E$2:$E$797,B12) -> 17 | G12: =_xlfn.MINIFS('Reference Log'!$A$2:$A$797,'Reference Log'!$E$2:$E$797,B12) -> 45932 | H12: =_xlfn.MAXIFS('Reference Log'!$A$2:$A$797,'Reference Log'!$E$2:$E$797,B12) -> 46279 | I12: =_xlfn.MAXIFS('Reference Log'!$D$2:$D$797,'Reference Log'!$E$2:$E$797,B12) -> 46291 | J12: Washington Square Mass Read-in | K12: Young People's Alliance & friends (tied, 5 hosts) | L12: 2 of 16
A13: 9 | B13: telos.haus | C13: Arts / community space | D13: Brooklyn | E13: =COUNTIF('Reference Log'!$E$2:$E$797,B13) -> 22 | F13: =SUMIFS('Reference Log'!$J$2:$J$797,'Reference Log'!$E$2:$E$797,B13) -> 16 | G13: =_xlfn.MINIFS('Reference Log'!$A$2:$A$797,'Reference Log'!$E$2:$E$797,B13) -> 45975 | H13: =_xlfn.MAXIFS('Reference Log'!$A$2:$A$797,'Reference Log'!$E$2:$E$797,B13) -> 46235 | I13: =_xlfn.MAXIFS('Reference Log'!$D$2:$D$797,'Reference Log'!$E$2:$E$797,B13) -> 46244 | J13: MO Gallery Exhibition (Free Offline Expo) | K13: NYC offline community (Let's Get Off Together) | L13: 7 of 19
A14: 10 | B14: Fort Greene Park | C14: Park / public space | D14: Fort Greene, Brooklyn | E14: =COUNTIF('Reference Log'!$E$2:$E$797,B14) -> 19 | F14: =SUMIFS('Reference Log'!$J$2:$J$797,'Reference Log'!$E$2:$E$797,B14) -> 10 | G14: =_xlfn.MINIFS('Reference Log'!$A$2:$A$797,'Reference Log'!$E$2:$E$797,B14) -> 45932 | H14: =_xlfn.MAXIFS('Reference Log'!$A$2:$A$797,'Reference Log'!$E$2:$E$797,B14) -> 46311 | I14: =_xlfn.MAXIFS('Reference Log'!$D$2:$D$797,'Reference Log'!$E$2:$E$797,B14) -> 46321 | J14: Falling Leaves Moon | K14: Kyle Barnes / Chimeras Collective | L14: 4 of 9
A15: 11 | B15: Undisclosed address — Fort Greene | C15: Undisclosed (neighborhood only) | D15: Fort Greene | E15: =COUNTIF('Reference Log'!$E$2:$E$797,B15) -> 17 | F15: =SUMIFS('Reference Log'!$J$2:$J$797,'Reference Log'!$E$2:$E$797,B15) -> 17 | G15: =_xlfn.MINIFS('Reference Log'!$A$2:$A$797,'Reference Log'!$E$2:$E$797,B15) -> 46004 | H15: =_xlfn.MAXIFS('Reference Log'!$A$2:$A$797,'Reference Log'!$E$2:$E$797,B15) -> 46311 | I15: =_xlfn.MAXIFS('Reference Log'!$D$2:$D$797,'Reference Log'!$E$2:$E$797,B15) -> 46323 | J15: Phone-Free Adelphi (weekly) | K15: Dan Fox (Phone-Free Adelphi) | L15: 17 of 17
A16: 12 | B16: Brooklyn Public Library – Central Library | C16: Library | D16: Grand Army Plaza, Brooklyn | E16: =COUNTIF('Reference Log'!$E$2:$E$797,B16) -> 14 | F16: =SUMIFS('Reference Log'!$J$2:$J$797,'Reference Log'!$E$2:$E$797,B16) -> 11 | G16: =_xlfn.MINIFS('Reference Log'!$A$2:$A$797,'Reference Log'!$E$2:$E$797,B16) -> 45932 | H16: =_xlfn.MAXIFS('Reference Log'!$A$2:$A$797,'Reference Log'!$E$2:$E$797,B16) -> 46279 | I16: =_xlfn.MAXIFS('Reference Log'!$D$2:$D$797,'Reference Log'!$E$2:$E$797,B16) -> 46284 | J16: AI and You | K16: Brooklyn Luddite Club | L16: 6 of 13
... A172: 168 | B172: Zuccotti Park | C172: Park / public space | D172: FiDi, Manhattan | E172: =COUNTIF('Reference Log'!$E$2:$E$797,B172) -> 1 | F172: =SUMIFS('Reference Log'!$J$2:$J$797,'Reference Log'!$E$2:$E$797,B172) -> 1 | G172: =_xlfn.MINIFS('Reference Log'!$A$2:$A$797,'Reference Log'!$E$2:$E$797,B172) -> 46099 | H172: =_xlfn.MAXIFS('Reference Log'!$A$2:$A$797,'Reference Log'!$E$2:$E$797,B172) -> 46099 | I172: =_xlfn.MAXIFS('Reference Log'!$D$2:$D$797,'Reference Log'!$E$2:$E$797,B172) -> 46113 | J172: St. Stupid's Day Parade | K172: Rude Mechanical Orchestra | L172: 1 of 1
A174: Note: 'Most common host' and 'Most recent event listed' are computed from the Reference Log at build time (not live formulas). Grey rows = organizer withheld the address and gave only a neighborhood.

Sheet Reference Log
A1: Issue date | B1: Issue | C1: Event | D1: Event date | E1: Venue | F1: Venue type | G1: Area / address | H1: Host (as listed) | I1: Issue link | J1: First mention in issue? (1/0)
A2: 45932 | B2: NYC Off Tech — OCTOBER (2025) | C2: Reconnect Phone-Free Field Trip | D2: 45934 | E2: Governors Island | F2: Park / public space | G2: Manhattan | H2: Reconnect | I2: https://buttondown.com/nycofftech/archive/nyc-off-tech-october/ | J2: =IF(COUNTIFS($E$2:E2,E2,$A$2:A2,A2)=1,1,0) -> 1
A3: 45932 | B3: NYC Off Tech — OCTOBER (2025) | C3: Harvest Moon Party | D3: 45937 | E3: Fort Greene Park | F3: Park / public space | G3: Fort Greene, Brooklyn | H3: Kyle Barnes / Chimeras Collective | I3: https://buttondown.com/nycofftech/archive/nyc-off-tech-october/ | J3: =IF(COUNTIFS($E$2:E3,E3,$A$2:A3,A3)=1,1,0) -> 1
A4: 45932 | B4: NYC Off Tech — OCTOBER (2025) | C4: SoRA Attention Lab "COALITION" | D4: 45937 | E4: Strother School of Radical Attention (SoRA) | F4: Arts / community space | G4: DUMBO, Brooklyn (listed as 'DUMBO') | H4: School of Radical Attention (SoRA) | I4: https://buttondown.com/nycofftech/archive/nyc-off-tech-october/ | J4: =IF(COUNTIFS($E$2:E4,E4,$A$2:A4,A4)=1,1,0) -> 1
A5: 45932 | B5: NYC Off Tech — OCTOBER (2025) | C5: ENSHITTIFICATION w/ Cory Doctorow & Lina Khan | D5: 45939 | E5: Brooklyn Public Library – Central Library | F5: Library | G5: Grand Army Plaza, Brooklyn | I5: https://buttondown.com/nycofftech/archive/nyc-off-tech-october/ | J5: =IF(COUNTIFS($E$2:E5,E5,$A$2:A5,A5)=1,1,0) -> 1
A6: 45932 | B6: NYC Off Tech — OCTOBER (2025) | C6: DELETE DAY | D6: 45940 | E6: Tompkins Square Park | F6: Park / public space | G6: East Village, Manhattan | H6: Time to Refuse | I6: https://buttondown.com/nycofftech/archive/nyc-off-tech-october/ | J6: =IF(COUNTIFS($E$2:E6,E6,$A$2:A6,A6)=1,1,0) -> 1
A7: 45932 | B7: NYC Off Tech — OCTOBER (2025) | C7: Say Hi IRL (tabling) | D7: 45944 | E7: Washington Square Park | F7: Park / public space | G7: Greenwich Village, Manhattan | H7: NYC Off Tech organizers | I7: https://buttondown.com/nycofftech/archive/nyc-off-tech-october/ | J7: =IF(COUNTIFS($E$2:E7,E7,$A$2:A7,A7)=1,1,0) -> 1
A8: 45932 | B8: NYC Off Tech — OCTOBER (2025) | C8: Come Say Hi to Friend AI | D8: 45949 | E8: Father Demo Square | F8: Park / public space | G8: 6th Ave & Bleecker, Manhattan | I8: https://buttondown.com/nycofftech/archive/nyc-off-tech-october/ | J8: =IF(COUNTIFS($E$2:E8,E8,$A$2:A8,A8)=1,1,0) -> 1
A9: 45932 | B9: NYC Off Tech — OCTOBER (2025) | C9: 'Monthly Molting' Ecology Workshop | D9: 45949 | E9: Prospect Park (incl. Boathouse, Fallkill Falls, Rose Garden) | F9: Park / public space | G9: Brooklyn | I9: https://buttondown.com/nycofftech/archive/nyc-off-tech-october/ | J9: =IF(COUNTIFS($E$2:E9,E9,$A$2:A9,A9)=1,1,0) -> 1
A10: 45932 | B10: NYC Off Tech — OCTOBER (2025) | C10: Offline Book Club: Superbloom | D10: 45953 | E10: Stavros Niarchos Foundation Library (NYPL) | F10: Library | G10: Midtown, Manhattan | H10: NYPL Offline Book Club | I10: https://buttondown.com/nycofftech/archive/nyc-off-tech-october/ | J10: =IF(COUNTIFS($E$2:E10,E10,$A$2:A10,A10)=1,1,0) -> 1
A11: 45932 | B11: NYC Off Tech — OCTOBER (2025) | C11: BOYB: Bring Your Own Book | D11: 45953 | E11: Undisclosed address — Crown Heights | F11: Undisclosed (neighborhood only) | G11: Crown Heights | H11: Connor Griffin | I11: https://buttondown.com/nycofftech/archive/nyc-off-tech-october/ | J11: =IF(COUNTIFS($E$2:E11,E11,$A$2:A11,A11)=1,1,0) -> 1
A12: 45932 | B12: NYC Off Tech — OCTOBER (2025) | C12: Attention Potlucks | D12: 45954 | E12: Undisclosed address — Crown Heights | F12: Undisclosed (neighborhood only) | G12: Crown Heights | H12: Connor Griffin | I12: https://buttondown.com/nycofftech/archive/nyc-off-tech-october/ | J12: =IF(COUNTIFS($E$2:E12,E12,$A$2:A12,A12)=1,1,0) -> 0
A13: 45932 | B13: NYC Off Tech — OCTOBER (2025) | C13: McGolrick Park Bird Club | D13: 45955 | E13: McGolrick Park | F13: Park / public space | G13: Greenpoint, Brooklyn | I13: https://buttondown.com/nycofftech/archive/nyc-off-tech-october/ | J13: =IF(COUNTIFS($E$2:E13,E13,$A$2:A13,A13)=1,1,0) -> 1
A14: 45932 | B14: NYC Off Tech — OCTOBER (2025) | C14: Community-Building Meditation | D14: 45957 | E14: Undisclosed address — Crown Heights | F14: Undisclosed (neighborhood only) | G14: Crown Heights | H14: Phil Nguyen | I14: https://buttondown.com/nycofftech/archive/nyc-off-tech-october/ | J14: =IF(COUNTIFS($E$2:E14,E14,$A$2:A14,A14)=1,1,0) -> 0
A15: 45932 | B15: NYC Off Tech — OCTOBER (2025) | C15: Pop-Up Spooky Walk | D15: 45961 | E15: Tompkins Square Park | F15: Park / public space | G15: East Village, Manhattan | I15: https://buttondown.com/nycofftech/archive/nyc-off-tech-october/ | J15: =IF(COUNTIFS($E$2:E15,E15,$A$2:A15,A15)=1,1,0) -> 0
A16: 45932 | B16: NYC Off Tech — OCTOBER (2025) | C16: RETOOLING | D16: 45962 | E16: Undisclosed address — Williamsburg | F16: Undisclosed (neighborhood only) | G16: Williamsburg | I16: https://buttondown.com/nycofftech/archive/nyc-off-tech-october/ | J16: =IF(COUNTIFS($E$2:E16,E16,$A$2:A16,A16)=1,1,0) -> 1
A17: 45947 | B17: NYC Off Tech Mid-October Updates (2025) | C17: Come Say Hi to Friend AI | D17: 45949 | E17: Father Demo Square | F17: Park / public space | G17: 6th Ave & Bleecker, Manhattan | I17: https://buttondown.com/nycofftech/archive/nyc-off-tech-mid-october-updates/ | J17: =IF(COUNTIFS($E$2:E17,E17,$A$2:A17,A17)=1,1,0) -> 1
A18: 45947 | B18: NYC Off Tech Mid-October Updates (2025) | C18: Pop-Up Spooky Walk | D18: 45961 | E18: Tompkins Square Park | F18: Park / public space | G18: East Village, Manhattan | I18: https://buttondown.com/nycofftech/archive/nyc-off-tech-mid-october-updates/ | J18: =IF(COUNTIFS($E$2:E18,E18,$A$2:A18,A18)=1,1,0) -> 1
A19: 45947 | B19: NYC Off Tech Mid-October Updates (2025) | C19: RETOOLING | D19: 45962 | E19: Madison Square Park | F19: Park / public space | G19: Flatiron, Manhattan | I19: https://buttondown.com/nycofftech/archive/nyc-off-tech-mid-october-updates/ | J19: =IF(COUNTIFS($E$2:E19,E19,$A$2:A19,A19)=1,1,0) -> 1
A20: 45962 | B20: NYC Off Tech — NOVEMBER | C20: RETOOLING | D20: 45962 | E20: Madison Square Park | F20: Park / public space | G20: Flatiron, Manhattan | I20: https://buttondown.com/nycofftech/archive/nyc-off-tech-november/ | J20: =IF(COUNTIFS($E$2:E20,E20,$A$2:A20,A20)=1,1,0) -> 1
A21: 45962 | B21: NYC Off Tech — NOVEMBER | C21: SoRA Attention Lab "COALITION" | D21: 45963 | E21: Strother School of Radical Attention (SoRA) | F21: Arts / community space | G21: DUMBO, Brooklyn (listed as 'DUMBO') | H21: School of Radical Attention (SoRA) | I21: https://buttondown.com/nycofftech/archive/nyc-off-tech-november/ | J21: =IF(COUNTIFS($E$2:E21,E21,$A$2:A21,A21)=1,1,0) -> 1
A22: 45962 | B22: NYC Off Tech — NOVEMBER | C22: Intentional Tech Use: Community Discussion | D22: 45963 | E22: XRoads Cafe Bushwick | F22: Cafe / bar / restaurant | G22: Bushwick, Brooklyn | H22: Logina Mostafa & Connor Griffin | I22: https://buttondown.com/nycofftech/archive/nyc-off-tech-november/ | J22: =IF(COUNTIFS($E$2:E22,E22,$A$2:A22,A22)=1,1,0) -> 1
A23: 45962 | B23: NYC Off Tech — NOVEMBER | C23: PSYCHIATRIST & SNACKS | D23: 45967 | E23: Undisclosed address — Bushwick | F23: Undisclosed (neighborhood only) | G23: Bushwick | H23: Rebecca Lipsitch (How Do We Play) | I23: https://buttondown.com/nycofftech/archive/nyc-off-tech-november/ | J23: =IF(COUNTIFS($E$2:E23,E23,$A$2:A23,A23)=1,1,0) -> 1
A24: 45962 | B24: NYC Off Tech — NOVEMBER | C24: You Don't Need a Smartphone | D24: 45967 | E24: Washington Square Park | F24: Park / public space | G24: Greenwich Village, Manhattan | H24: August Lamm & friends | I24: https://buttondown.com/nycofftech/archive/nyc-off-tech-november/ | J24: =IF(COUNTIFS($E$2:E24,E24,$A$2:A24,A24)=1,1,0) -> 1
A25: 45962 | B25: NYC Off Tech — NOVEMBER | C25: New Luddism conference | D25: 45968 | E25: Columbia University (incl. The Forum / Bollinger Forum) | F25: University | G25: Morningside Heights, Manhattan | I25: https://buttondown.com/nycofftech/archive/nyc-off-tech-november/ | J25: =IF(COUNTIFS($E$2:E25,E25,$A$2:A25,A25)=1,1,0) -> 1
A26: 45962 | B26: NYC Off Tech — NOVEMBER | C26: Beaver Moon Party | D26: 45968 | E26: Undisclosed address — Park Slope | F26: Undisclosed (neighborhood only) | G26: Park Slope | H26: Kyle Barnes / Chimeras Collective | I26: https://buttondown.com/nycofftech/archive/nyc-off-tech-november/ | J26: =IF(COUNTIFS($E$2:E26,E26,$A$2:A26,A26)=1,1,0) -> 1
A27: 45962 | B27: NYC Off Tech — NOVEMBER | C27: ScreenMime | D27: 45969 | E27: Apple Store Fifth Avenue ('the Cube') | F27: Retail (protest site) | G27: Fifth Ave & Central Park S, Manhattan | I27: https://buttondown.com/nycofftech/archive/nyc-off-tech-november/ | J27: =IF(COUNTIFS($E$2:E27,E27,$A$2:A27,A27)=1,1,0) -> 1
A28: 45962 | B28: NYC Off Tech — NOVEMBER | C28: M.A.G.L.A.R.&O! | D28: 45970 | E28: Undisclosed address — Crown Heights | F28: Undisclosed (neighborhood only) | G28: Crown Heights | H28: M.A.G.L.A.R.O! | I28: https://buttondown.com/nycofftech/archive/nyc-off-tech-november/ | J28: =IF(COUNTIFS($E$2:E28,E28,$A$2:A28,A28)=1,1,0) -> 1
A29: 45962 | B29: NYC Off Tech — NOVEMBER | C29: Study Corps: Poetry Intervention | D29: 45972 | E29: Rockefeller Center | F29: Park / public space | G29: Midtown, Manhattan | H29: SoRA Study Corps | I29: https://buttondown.com/nycofftech/archive/nyc-off-tech-november/ | J29: =IF(COUNTIFS($E$2:E29,E29,$A$2:A29,A29)=1,1,0) -> 1
A30: 45962 | B30: NYC Off Tech — NOVEMBER | C30: BE A NEW YORKER 101 | D30: 45976 | E30: Tompkins Square Park | F30: Park / public space | G30: East Village, Manhattan | H30: Lamp Club | I30: https://buttondown.com/nycofftech/archive/nyc-off-tech-november/ | J30: =IF(COUNTIFS($E$2:E30,E30,$A$2:A30,A30)=1,1,0) -> 1
A31: 45962 | B31: NYC Off Tech — NOVEMBER | C31: Passion Party: Parallel Play | D31: 45979 | E31: Undisclosed address — Bushwick | F31: Undisclosed (neighborhood only) | G31: Bushwick | H31: Rebecca Lipsitch (How Do We Play) | I31: https://buttondown.com/nycofftech/archive/nyc-off-tech-november/ | J31: =IF(COUNTIFS($E$2:E31,E31,$A$2:A31,A31)=1,1,0) -> 0
A32: 45962 | B32: NYC Off Tech — NOVEMBER | C32: SoRA Train-the-Trainer | D32: 45980 | E32: Strother School of Radical Attention (SoRA) | F32: Arts / community space | G32: DUMBO, Brooklyn (listed as 'DUMBO') | H32: School of Radical Attention (SoRA) | I32: https://buttondown.com/nycofftech/archive/nyc-off-tech-november/ | J32: =IF(COUNTIFS($E$2:E32,E32,$A$2:A32,A32)=1,1,0) -> 0
A33: 45962 | B33: NYC Off Tech — NOVEMBER | C33: Offline Book Club: Filterworld | D33: 45981 | E33: Stavros Niarchos Foundation Library (NYPL) | F33: Library | G33: Midtown, Manhattan | H33: NYPL Offline Book Club | I33: https://buttondown.com/nycofftech/archive/nyc-off-tech-november/ | J33: =IF(COUNTIFS($E$2:E33,E33,$A$2:A33,A33)=1,1,0) -> 1
A34: 45962 | B34: NYC Off Tech — NOVEMBER | C34: Attention Lab SANCTUARY | D34: 45981 | E34: Strother School of Radical Attention (SoRA) | F34: Arts / community space | G34: DUMBO, Brooklyn (listed as 'DUMBO') | H34: School of Radical Attention (SoRA) | I34: https://buttondown.com/nycofftech/archive/nyc-off-tech-november/ | J34: =IF(COUNTIFS($E$2:E34,E34,$A$2:A34,A34)=1,1,0) -> 0
A35: 45962 | B35: NYC Off Tech — NOVEMBER | C35: 'Monthly Molting' Ecology Workshop | D35: 45984 | E35: Prospect Park (incl. Boathouse, Fallkill Falls, Rose Garden) | F35: Park / public space | G35: Brooklyn | H35: Kyle Barnes / Chimeras Collective | I35: https://buttondown.com/nycofftech/archive/nyc-off-tech-november/ | J35: =IF(COUNTIFS($E$2:E35,E35,$A$2:A35,A35)=1,1,0) -> 1
A36: 45962 | B36: NYC Off Tech — NOVEMBER | C36: Awareness-Building Meditation | D36: 45985 | E36: Undisclosed address — Crown Heights | F36: Undisclosed (neighborhood only) | G36: Crown Heights | H36: Phil Nguyen | I36: https://buttondown.com/nycofftech/archive/nyc-off-tech-november/ | J36: =IF(COUNTIFS($E$2:E36,E36,$A$2:A36,A36)=1,1,0) -> 0
A37: 45962 | B37: NYC Off Tech — NOVEMBER | C37: BYOB: Bring Your Own Book | D37: 45986 | E37: Undisclosed address — Crown Heights | F37: Undisclosed (neighborhood only) | G37: Crown Heights | H37: Connor Griffin | I37: https://buttondown.com/nycofftech/archive/nyc-off-tech-november/ | J37: =IF(COUNTIFS($E$2:E37,E37,$A$2:A37,A37)=1,1,0) -> 0
A38: 45962 | B38: NYC Off Tech — NOVEMBER | C38: BUY NOTHING DAY | D38: 45989 | E38: Tompkins Square Park | F38: Park / public space | G38: East Village, Manhattan | I38: https://buttondown.com/nycofftech/archive/nyc-off-tech-november/ | J38: =IF(COUNTIFS($E$2:E38,E38,$A$2:A38,A38)=1,1,0) -> 0
A39: 45962 | B39: NYC Off Tech — NOVEMBER | C39: McGolrick Park Bird Club | D39: 45990 | E39: McGolrick Park | F39: Park / public space | G39: Greenpoint, Brooklyn | I39: https://buttondown.com/nycofftech/archive/nyc-off-tech-november/ | J39: =IF(COUNTIFS($E$2:E39,E39,$A$2:A39,A39)=1,1,0) -> 1
A40: 45962 | B40: NYC Off Tech — NOVEMBER | C40: Spotify Deletion Dance Party | D40: 45997 | E40: boshi's place | F40: Arts / community space | G40: East Williamsburg, Brooklyn | I40: https://buttondown.com/nycofftech/archive/nyc-off-tech-november/ | J40: =IF(COUNTIFS($E$2:E40,E40,$A$2:A40,A40)=1,1,0) -> 1
...

Sheet About
A1: About this workbook
A3: Source | B3: Every issue in the NYC Off Tech archive (buttondown.com/nycofftech/archive), 27 issues from Oct 2, 2025 through Oct 16, 2026, read Oct 26, 2026.
A4: What counts as a reference | B4: One event listing in one issue. If a mid-month update re-lists an event from the monthly issue, that's a second reference. A recurring series (e.g. weekly Crafternoon) counts once per issue, dated to its last listed occurrence in that issue.
A5: Times referenced vs. Issues referencing | B5: 'Times referenced' counts event listings; 'Issues referencing' counts how many distinct issues mention the venue at all.
A6: Most recent reference | B6: Latest issue that listed the venue. 'Latest event date listed' can be in the future (e.g. November events in the mid-October issue).
A7: Most common host | B7: Mode of the hosts named in listings for that venue; blank-host listings are ignored. Ties are broken by most recent listing and flagged. Host names were lightly normalized (e.g. 'Chimeras Collective' and 'Kyle Barnes' merged; all 'SoRA' variants merged; Study Corps kept separate). For the Summer of Ludd festival schedule, events without a named host are credited to Summer of Ludd.
A8: Venue merges | B8: Name variants were merged: e.g. 'Tompkins Sq. Park'/'Hare Krishna Tree' → Tompkins Square Park; '15 Rutherford Pl.'/'Quaker Meeting House'/'Earth Chxrch' → 15th Street Quaker Meeting House; all SNFL rooms → Stavros Niarchos Foundation Library; 'Central Library'/'Bklyn Central Library' → BPL Central Library; Forum/Bollinger Forum → Columbia; 'the Cube' → Apple Store Fifth Ave; Fallkill Falls/Boathouse/Rose Garden → Prospect Park; 'NoAD' → National Academy of Design.
A9: DUMBO | B9: SoRA events listed only as 'DUMBO' are attributed to the Strother School of Radical Attention's DUMBO space (the newsletter places SoRA in Dumbo). SoRA Attention Labs with no location given were treated the same.
A10: Excluded | B10: Online/Zoom/Jitsi events, 'TBA'/'TBD', 'Various locations', deadlines, and city-only locations (Kenya, Philadelphia, 'Brooklyn'). Neighborhood-only private addresses ARE included as grey 'Undisclosed address — <neighborhood>' rows.
A11: Caveat | B11: Listings were extracted from each issue's web page text; a few calendar-grid-only items with no stated location may be missed, and some event details are images in the original.
